2021-01-23 00:06:43,404 ERROR 96603 nodejs.ClusterClientNoResponseError: client no response in 384277ms exceeding maxIdleTime 60000ms, maybe the connection is close on other side.
    at Timeout._onTimeout (/Users/sherily/Desktop/Petcity/Repo/petcity-back/node_modules/cluster-client/lib/leader.js:77:23)
    at listOnTimeout (node:internal/timers:556:17)
    at processTimers (node:internal/timers:499:7)
name: "ClusterClientNoResponseError"
pid: 96603
hostname: xiejialis-MacBook-Pro.local

2021-01-23 01:19:14,992 ERROR 96603 nodejs.ClusterClientNoResponseError: client no response in 1730147ms exceeding maxIdleTime 60000ms, maybe the connection is close on other side.
    at Timeout._onTimeout (/Users/sherily/Desktop/Petcity/Repo/petcity-back/node_modules/cluster-client/lib/leader.js:77:23)
    at listOnTimeout (node:internal/timers:556:17)
    at processTimers (node:internal/timers:499:7)
name: "ClusterClientNoResponseError"
pid: 96603
hostname: xiejialis-MacBook-Pro.local

2021-01-23 01:22:27,212 ERROR 96603 nodejs.ClusterClientNoResponseError: client no response in 132185ms exceeding maxIdleTime 60000ms, maybe the connection is close on other side.
    at Timeout._onTimeout (/Users/sherily/Desktop/Petcity/Repo/petcity-back/node_modules/cluster-client/lib/leader.js:77:23)
    at listOnTimeout (node:internal/timers:556:17)
    at processTimers (node:internal/timers:499:7)
name: "ClusterClientNoResponseError"
pid: 96603
hostname: xiejialis-MacBook-Pro.local

2021-01-23 01:27:13,829 ERROR 96603 nodejs.ClusterClientNoResponseError: client no response in 75422ms exceeding maxIdleTime 60000ms, maybe the connection is close on other side.
    at Timeout._onTimeout (/Users/sherily/Desktop/Petcity/Repo/petcity-back/node_modules/cluster-client/lib/leader.js:77:23)
    at listOnTimeout (node:internal/timers:556:17)
    at processTimers (node:internal/timers:499:7)
name: "ClusterClientNoResponseError"
pid: 96603
hostname: xiejialis-MacBook-Pro.local

2021-01-23 01:34:09,587 ERROR 96603 nodejs.ClusterClientNoResponseError: client no response in 95649ms exceeding maxIdleTime 60000ms, maybe the connection is close on other side.
    at Timeout._onTimeout (/Users/sherily/Desktop/Petcity/Repo/petcity-back/node_modules/cluster-client/lib/leader.js:77:23)
    at listOnTimeout (node:internal/timers:556:17)
    at processTimers (node:internal/timers:499:7)
name: "ClusterClientNoResponseError"
pid: 96603
hostname: xiejialis-MacBook-Pro.local

2021-01-23 01:36:26,322 ERROR 96603 nodejs.ClusterClientNoResponseError: client no response in 95959ms exceeding maxIdleTime 60000ms, maybe the connection is close on other side.
    at Timeout._onTimeout (/Users/sherily/Desktop/Petcity/Repo/petcity-back/node_modules/cluster-client/lib/leader.js:77:23)
    at listOnTimeout (node:internal/timers:556:17)
    at processTimers (node:internal/timers:499:7)
name: "ClusterClientNoResponseError"
pid: 96603
hostname: xiejialis-MacBook-Pro.local

2021-01-23 01:38:48,334 ERROR 96603 nodejs.ClusterClientNoResponseError: client no response in 101984ms exceeding maxIdleTime 60000ms, maybe the connection is close on other side.
    at Timeout._onTimeout (/Users/sherily/Desktop/Petcity/Repo/petcity-back/node_modules/cluster-client/lib/leader.js:77:23)
    at listOnTimeout (node:internal/timers:556:17)
    at processTimers (node:internal/timers:499:7)
name: "ClusterClientNoResponseError"
pid: 96603
hostname: xiejialis-MacBook-Pro.local

2021-01-23 01:57:27,972 ERROR 96603 nodejs.ClusterClientNoResponseError: client no response in 981988ms exceeding maxIdleTime 60000ms, maybe the connection is close on other side.
    at Timeout._onTimeout (/Users/sherily/Desktop/Petcity/Repo/petcity-back/node_modules/cluster-client/lib/leader.js:77:23)
    at listOnTimeout (node:internal/timers:556:17)
    at processTimers (node:internal/timers:499:7)
name: "ClusterClientNoResponseError"
pid: 96603
hostname: xiejialis-MacBook-Pro.local

2021-01-23 02:00:30,332 ERROR 96603 nodejs.ClusterClientNoResponseError: client no response in 82278ms exceeding maxIdleTime 60000ms, maybe the connection is close on other side.
    at Timeout._onTimeout (/Users/sherily/Desktop/Petcity/Repo/petcity-back/node_modules/cluster-client/lib/leader.js:77:23)
    at listOnTimeout (node:internal/timers:556:17)
    at processTimers (node:internal/timers:499:7)
name: "ClusterClientNoResponseError"
pid: 96603
hostname: xiejialis-MacBook-Pro.local

2021-01-23 02:02:10,821 ERROR 96603 nodejs.ClusterClientNoResponseError: client no response in 60457ms exceeding maxIdleTime 60000ms, maybe the connection is close on other side.
    at Timeout._onTimeout (/Users/sherily/Desktop/Petcity/Repo/petcity-back/node_modules/cluster-client/lib/leader.js:77:23)
    at listOnTimeout (node:internal/timers:556:17)
    at processTimers (node:internal/timers:499:7)
name: "ClusterClientNoResponseError"
pid: 96603
hostname: xiejialis-MacBook-Pro.local

2021-01-23 02:49:56,711 ERROR 96603 nodejs.ClusterClientNoResponseError: client no response in 2428699ms exceeding maxIdleTime 60000ms, maybe the connection is close on other side.
    at Timeout._onTimeout (/Users/sherily/Desktop/Petcity/Repo/petcity-back/node_modules/cluster-client/lib/leader.js:77:23)
    at listOnTimeout (node:internal/timers:556:17)
    at processTimers (node:internal/timers:499:7)
name: "ClusterClientNoResponseError"
pid: 96603
hostname: xiejialis-MacBook-Pro.local

2021-01-23 02:59:51,775 ERROR 96603 nodejs.ClusterClientNoResponseError: client no response in 121011ms exceeding maxIdleTime 60000ms, maybe the connection is close on other side.
    at Timeout._onTimeout (/Users/sherily/Desktop/Petcity/Repo/petcity-back/node_modules/cluster-client/lib/leader.js:77:23)
    at listOnTimeout (node:internal/timers:556:17)
    at processTimers (node:internal/timers:499:7)
name: "ClusterClientNoResponseError"
pid: 96603
hostname: xiejialis-MacBook-Pro.local

2021-01-23 03:02:07,402 ERROR 96603 nodejs.ClusterClientNoResponseError: client no response in 95600ms exceeding maxIdleTime 60000ms, maybe the connection is close on other side.
    at Timeout._onTimeout (/Users/sherily/Desktop/Petcity/Repo/petcity-back/node_modules/cluster-client/lib/leader.js:77:23)
    at listOnTimeout (node:internal/timers:556:17)
    at processTimers (node:internal/timers:499:7)
name: "ClusterClientNoResponseError"
pid: 96603
hostname: xiejialis-MacBook-Pro.local

2021-01-23 03:07:05,696 ERROR 96603 nodejs.ClusterClientNoResponseError: client no response in 68803ms exceeding maxIdleTime 60000ms, maybe the connection is close on other side.
    at Timeout._onTimeout (/Users/sherily/Desktop/Petcity/Repo/petcity-back/node_modules/cluster-client/lib/leader.js:77:23)
    at listOnTimeout (node:internal/timers:556:17)
    at processTimers (node:internal/timers:499:7)
name: "ClusterClientNoResponseError"
pid: 96603
hostname: xiejialis-MacBook-Pro.local

2021-01-23 03:08:53,925 ERROR 96603 nodejs.ClusterClientNoResponseError: client no response in 68191ms exceeding maxIdleTime 60000ms, maybe the connection is close on other side.
    at Timeout._onTimeout (/Users/sherily/Desktop/Petcity/Repo/petcity-back/node_modules/cluster-client/lib/leader.js:77:23)
    at listOnTimeout (node:internal/timers:556:17)
    at processTimers (node:internal/timers:499:7)
name: "ClusterClientNoResponseError"
pid: 96603
hostname: xiejialis-MacBook-Pro.local

2021-01-23 04:25:14,323 ERROR 96603 nodejs.ClusterClientNoResponseError: client no response in 4347195ms exceeding maxIdleTime 60000ms, maybe the connection is close on other side.
    at Timeout._onTimeout (/Users/sherily/Desktop/Petcity/Repo/petcity-back/node_modules/cluster-client/lib/leader.js:77:23)
    at listOnTimeout (node:internal/timers:556:17)
    at processTimers (node:internal/timers:499:7)
name: "ClusterClientNoResponseError"
pid: 96603
hostname: xiejialis-MacBook-Pro.local

2021-01-23 04:29:41,865 ERROR 96603 nodejs.ClusterClientNoResponseError: client no response in 146884ms exceeding maxIdleTime 60000ms, maybe the connection is close on other side.
    at Timeout._onTimeout (/Users/sherily/Desktop/Petcity/Repo/petcity-back/node_modules/cluster-client/lib/leader.js:77:23)
    at listOnTimeout (node:internal/timers:556:17)
    at processTimers (node:internal/timers:499:7)
name: "ClusterClientNoResponseError"
pid: 96603
hostname: xiejialis-MacBook-Pro.local

2021-01-23 05:10:31,387 ERROR 96603 nodejs.ClusterClientNoResponseError: client no response in 2283372ms exceeding maxIdleTime 60000ms, maybe the connection is close on other side.
    at Timeout._onTimeout (/Users/sherily/Desktop/Petcity/Repo/petcity-back/node_modules/cluster-client/lib/leader.js:77:23)
    at listOnTimeout (node:internal/timers:556:17)
    at processTimers (node:internal/timers:499:7)
name: "ClusterClientNoResponseError"
pid: 96603
hostname: xiejialis-MacBook-Pro.local

2021-01-23 05:48:47,148 ERROR 96603 nodejs.ClusterClientNoResponseError: client no response in 2255658ms exceeding maxIdleTime 60000ms, maybe the connection is close on other side.
    at Timeout._onTimeout (/Users/sherily/Desktop/Petcity/Repo/petcity-back/node_modules/cluster-client/lib/leader.js:77:23)
    at listOnTimeout (node:internal/timers:556:17)
    at processTimers (node:internal/timers:499:7)
name: "ClusterClientNoResponseError"
pid: 96603
hostname: xiejialis-MacBook-Pro.local

2021-01-23 07:49:36,333 ERROR 96603 nodejs.ClusterClientNoResponseError: client no response in 7207542ms exceeding maxIdleTime 60000ms, maybe the connection is close on other side.
    at Timeout._onTimeout (/Users/sherily/Desktop/Petcity/Repo/petcity-back/node_modules/cluster-client/lib/leader.js:77:23)
    at listOnTimeout (node:internal/timers:556:17)
    at processTimers (node:internal/timers:499:7)
name: "ClusterClientNoResponseError"
pid: 96603
hostname: xiejialis-MacBook-Pro.local

2021-01-23 07:53:07,787 ERROR 96603 nodejs.ClusterClientNoResponseError: client no response in 171443ms exceeding maxIdleTime 60000ms, maybe the connection is close on other side.
    at Timeout._onTimeout (/Users/sherily/Desktop/Petcity/Repo/petcity-back/node_modules/cluster-client/lib/leader.js:77:23)
    at listOnTimeout (node:internal/timers:556:17)
    at processTimers (node:internal/timers:499:7)
name: "ClusterClientNoResponseError"
pid: 96603
hostname: xiejialis-MacBook-Pro.local

2021-01-23 07:56:08,189 ERROR 96603 nodejs.ClusterClientNoResponseError: client no response in 140459ms exceeding maxIdleTime 60000ms, maybe the connection is close on other side.
    at Timeout._onTimeout (/Users/sherily/Desktop/Petcity/Repo/petcity-back/node_modules/cluster-client/lib/leader.js:77:23)
    at listOnTimeout (node:internal/timers:556:17)
    at processTimers (node:internal/timers:499:7)
name: "ClusterClientNoResponseError"
pid: 96603
hostname: xiejialis-MacBook-Pro.local

2021-01-23 07:59:09,322 ERROR 96603 nodejs.ClusterClientNoResponseError: client no response in 140299ms exceeding maxIdleTime 60000ms, maybe the connection is close on other side.
    at Timeout._onTimeout (/Users/sherily/Desktop/Petcity/Repo/petcity-back/node_modules/cluster-client/lib/leader.js:77:23)
    at listOnTimeout (node:internal/timers:556:17)
    at processTimers (node:internal/timers:499:7)
name: "ClusterClientNoResponseError"
pid: 96603
hostname: xiejialis-MacBook-Pro.local

2021-01-23 08:01:08,100 ERROR 96603 nodejs.ClusterClientNoResponseError: client no response in 78005ms exceeding maxIdleTime 60000ms, maybe the connection is close on other side.
    at Timeout._onTimeout (/Users/sherily/Desktop/Petcity/Repo/petcity-back/node_modules/cluster-client/lib/leader.js:77:23)
    at listOnTimeout (node:internal/timers:556:17)
    at processTimers (node:internal/timers:499:7)
name: "ClusterClientNoResponseError"
pid: 96603
hostname: xiejialis-MacBook-Pro.local

2021-01-23 08:03:18,937 ERROR 96603 nodejs.ClusterClientNoResponseError: client no response in 90796ms exceeding maxIdleTime 60000ms, maybe the connection is close on other side.
    at Timeout._onTimeout (/Users/sherily/Desktop/Petcity/Repo/petcity-back/node_modules/cluster-client/lib/leader.js:77:23)
    at listOnTimeout (node:internal/timers:556:17)
    at processTimers (node:internal/timers:499:7)
name: "ClusterClientNoResponseError"
pid: 96603
hostname: xiejialis-MacBook-Pro.local

2021-01-23 08:05:26,337 ERROR 96603 nodejs.ClusterClientNoResponseError: client no response in 86657ms exceeding maxIdleTime 60000ms, maybe the connection is close on other side.
    at Timeout._onTimeout (/Users/sherily/Desktop/Petcity/Repo/petcity-back/node_modules/cluster-client/lib/leader.js:77:23)
    at listOnTimeout (node:internal/timers:556:17)
    at processTimers (node:internal/timers:499:7)
name: "ClusterClientNoResponseError"
pid: 96603
hostname: xiejialis-MacBook-Pro.local

2021-01-23 08:35:54,188 ERROR 96603 nodejs.ClusterClientNoResponseError: client no response in 1787093ms exceeding maxIdleTime 60000ms, maybe the connection is close on other side.
    at Timeout._onTimeout (/Users/sherily/Desktop/Petcity/Repo/petcity-back/node_modules/cluster-client/lib/leader.js:77:23)
    at listOnTimeout (node:internal/timers:556:17)
    at processTimers (node:internal/timers:499:7)
name: "ClusterClientNoResponseError"
pid: 96603
hostname: xiejialis-MacBook-Pro.local

2021-01-23 08:43:04,770 ERROR 96603 nodejs.ClusterClientNoResponseError: client no response in 330504ms exceeding maxIdleTime 60000ms, maybe the connection is close on other side.
    at Timeout._onTimeout (/Users/sherily/Desktop/Petcity/Repo/petcity-back/node_modules/cluster-client/lib/leader.js:77:23)
    at listOnTimeout (node:internal/timers:556:17)
    at processTimers (node:internal/timers:499:7)
name: "ClusterClientNoResponseError"
pid: 96603
hostname: xiejialis-MacBook-Pro.local

2021-01-23 09:10:48,039 ERROR 96603 nodejs.ClusterClientNoResponseError: client no response in 1623207ms exceeding maxIdleTime 60000ms, maybe the connection is close on other side.
    at Timeout._onTimeout (/Users/sherily/Desktop/Petcity/Repo/petcity-back/node_modules/cluster-client/lib/leader.js:77:23)
    at listOnTimeout (node:internal/timers:556:17)
    at processTimers (node:internal/timers:499:7)
name: "ClusterClientNoResponseError"
pid: 96603
hostname: xiejialis-MacBook-Pro.local

2021-01-23 09:16:46,899 ERROR 96603 nodejs.ClusterClientNoResponseError: client no response in 255862ms exceeding maxIdleTime 60000ms, maybe the connection is close on other side.
    at Timeout._onTimeout (/Users/sherily/Desktop/Petcity/Repo/petcity-back/node_modules/cluster-client/lib/leader.js:77:23)
    at listOnTimeout (node:internal/timers:556:17)
    at processTimers (node:internal/timers:499:7)
name: "ClusterClientNoResponseError"
pid: 96603
hostname: xiejialis-MacBook-Pro.local

2021-01-23 09:23:47,905 ERROR 96603 nodejs.ClusterClientNoResponseError: client no response in 224395ms exceeding maxIdleTime 60000ms, maybe the connection is close on other side.
    at Timeout._onTimeout (/Users/sherily/Desktop/Petcity/Repo/petcity-back/node_modules/cluster-client/lib/leader.js:77:23)
    at listOnTimeout (node:internal/timers:556:17)
    at processTimers (node:internal/timers:499:7)
name: "ClusterClientNoResponseError"
pid: 96603
hostname: xiejialis-MacBook-Pro.local

2021-01-23 09:27:20,136 ERROR 96603 nodejs.ClusterClientNoResponseError: client no response in 172202ms exceeding maxIdleTime 60000ms, maybe the connection is close on other side.
    at Timeout._onTimeout (/Users/sherily/Desktop/Petcity/Repo/petcity-back/node_modules/cluster-client/lib/leader.js:77:23)
    at listOnTimeout (node:internal/timers:556:17)
    at processTimers (node:internal/timers:499:7)
name: "ClusterClientNoResponseError"
pid: 96603
hostname: xiejialis-MacBook-Pro.local

2021-01-23 09:31:25,583 ERROR 96603 nodejs.ClusterClientNoResponseError: client no response in 185424ms exceeding maxIdleTime 60000ms, maybe the connection is close on other side.
    at Timeout._onTimeout (/Users/sherily/Desktop/Petcity/Repo/petcity-back/node_modules/cluster-client/lib/leader.js:77:23)
    at listOnTimeout (node:internal/timers:556:17)
    at processTimers (node:internal/timers:499:7)
name: "ClusterClientNoResponseError"
pid: 96603
hostname: xiejialis-MacBook-Pro.local

2021-01-23 09:34:16,654 ERROR 96603 nodejs.ClusterClientNoResponseError: client no response in 131031ms exceeding maxIdleTime 60000ms, maybe the connection is close on other side.
    at Timeout._onTimeout (/Users/sherily/Desktop/Petcity/Repo/petcity-back/node_modules/cluster-client/lib/leader.js:77:23)
    at listOnTimeout (node:internal/timers:556:17)
    at processTimers (node:internal/timers:499:7)
name: "ClusterClientNoResponseError"
pid: 96603
hostname: xiejialis-MacBook-Pro.local

2021-01-23 09:37:08,404 ERROR 96603 nodejs.ClusterClientNoResponseError: client no response in 131708ms exceeding maxIdleTime 60000ms, maybe the connection is close on other side.
    at Timeout._onTimeout (/Users/sherily/Desktop/Petcity/Repo/petcity-back/node_modules/cluster-client/lib/leader.js:77:23)
    at listOnTimeout (node:internal/timers:556:17)
    at processTimers (node:internal/timers:499:7)
name: "ClusterClientNoResponseError"
pid: 96603
hostname: xiejialis-MacBook-Pro.local

2021-01-23 09:40:27,675 ERROR 96603 nodejs.ClusterClientNoResponseError: client no response in 159255ms exceeding maxIdleTime 60000ms, maybe the connection is close on other side.
    at Timeout._onTimeout (/Users/sherily/Desktop/Petcity/Repo/petcity-back/node_modules/cluster-client/lib/leader.js:77:23)
    at listOnTimeout (node:internal/timers:556:17)
    at processTimers (node:internal/timers:499:7)
name: "ClusterClientNoResponseError"
pid: 96603
hostname: xiejialis-MacBook-Pro.local

2021-01-23 10:00:13,582 ERROR 96603 nodejs.ClusterClientNoResponseError: client no response in 1069128ms exceeding maxIdleTime 60000ms, maybe the connection is close on other side.
    at Timeout._onTimeout (/Users/sherily/Desktop/Petcity/Repo/petcity-back/node_modules/cluster-client/lib/leader.js:77:23)
    at listOnTimeout (node:internal/timers:556:17)
    at processTimers (node:internal/timers:499:7)
name: "ClusterClientNoResponseError"
pid: 96603
hostname: xiejialis-MacBook-Pro.local

2021-01-23 11:15:02,383 ERROR 96603 nodejs.ClusterClientNoResponseError: client no response in 4383373ms exceeding maxIdleTime 60000ms, maybe the connection is close on other side.
    at Timeout._onTimeout (/Users/sherily/Desktop/Petcity/Repo/petcity-back/node_modules/cluster-client/lib/leader.js:77:23)
    at listOnTimeout (node:internal/timers:556:17)
    at processTimers (node:internal/timers:499:7)
name: "ClusterClientNoResponseError"
pid: 96603
hostname: xiejialis-MacBook-Pro.local

2021-01-23 13:17:20,998 ERROR 96603 nodejs.ClusterClientNoResponseError: client no response in 132454ms exceeding maxIdleTime 60000ms, maybe the connection is close on other side.
    at Timeout._onTimeout (/Users/sherily/Desktop/Petcity/Repo/petcity-back/node_modules/cluster-client/lib/leader.js:77:23)
    at listOnTimeout (node:internal/timers:556:17)
    at processTimers (node:internal/timers:499:7)
name: "ClusterClientNoResponseError"
pid: 96603
hostname: xiejialis-MacBook-Pro.local

2021-01-23 13:24:54,100 ERROR 96603 nodejs.ClusterClientNoResponseError: client no response in 273001ms exceeding maxIdleTime 60000ms, maybe the connection is close on other side.
    at Timeout._onTimeout (/Users/sherily/Desktop/Petcity/Repo/petcity-back/node_modules/cluster-client/lib/leader.js:77:23)
    at listOnTimeout (node:internal/timers:556:17)
    at processTimers (node:internal/timers:499:7)
name: "ClusterClientNoResponseError"
pid: 96603
hostname: xiejialis-MacBook-Pro.local

2021-01-23 17:22:51,755 ERROR 96603 nodejs.ClusterClientNoResponseError: client no response in 161083ms exceeding maxIdleTime 60000ms, maybe the connection is close on other side.
    at Timeout._onTimeout (/Users/sherily/Desktop/Petcity/Repo/petcity-back/node_modules/cluster-client/lib/leader.js:77:23)
    at listOnTimeout (node:internal/timers:556:17)
    at processTimers (node:internal/timers:499:7)
name: "ClusterClientNoResponseError"
pid: 96603
hostname: xiejialis-MacBook-Pro.local

2021-01-23 19:05:29,854 ERROR 35893 [-/192.168.31.88/-/7ms POST /api/v1/saveAvatar] nodejs.TypeError: this.service.tools.getUploadFile is not a function
    at UserController.saveAvatar (/Users/sherily/Desktop/Petcity/Repo/petcity-back/app/controller/user.js:116:50)
    at processTicksAndRejections (node:internal/process/task_queues:93:5)
    at async /Users/sherily/Desktop/Petcity/Repo/petcity-back/node_modules/koa-static-cache/index.js:39:63
    at async robotMiddleware (/Users/sherily/Desktop/Petcity/Repo/petcity-back/app/middleware/robot.js:11:13)
    at async /Users/sherily/Desktop/Petcity/Repo/petcity-back/node_modules/egg-development/app/middleware/egg_loader_trace.js:9:50
    at async xframe (/Users/sherily/Desktop/Petcity/Repo/petcity-back/node_modules/egg-security/lib/middlewares/xframe.js:7:5)
    at async xssProtection (/Users/sherily/Desktop/Petcity/Repo/petcity-back/node_modules/egg-security/lib/middlewares/xssProtection.js:7:5)
    at async nosniff (/Users/sherily/Desktop/Petcity/Repo/petcity-back/node_modules/egg-security/lib/middlewares/nosniff.js:8:5)
    at async noopen (/Users/sherily/Desktop/Petcity/Repo/petcity-back/node_modules/egg-security/lib/middlewares/noopen.js:8:5)
    at async session (/Users/sherily/Desktop/Petcity/Repo/petcity-back/node_modules/koa-session/index.js:41:7)

pid: 35893
hostname: xiejialis-MacBook-Pro.local

2021-01-23 19:06:48,851 ERROR 36134 [-/192.168.31.88/-/17ms POST /api/v1/saveAvatar] nodejs.ReferenceError: fs is not defined
    at UserController.saveAvatar (/Users/sherily/Desktop/Petcity/Repo/petcity-back/app/controller/user.js:118:33)
    at processTicksAndRejections (node:internal/process/task_queues:93:5)
    at async /Users/sherily/Desktop/Petcity/Repo/petcity-back/node_modules/koa-static-cache/index.js:39:63
    at async robotMiddleware (/Users/sherily/Desktop/Petcity/Repo/petcity-back/app/middleware/robot.js:11:13)
    at async /Users/sherily/Desktop/Petcity/Repo/petcity-back/node_modules/egg-development/app/middleware/egg_loader_trace.js:9:50
    at async xframe (/Users/sherily/Desktop/Petcity/Repo/petcity-back/node_modules/egg-security/lib/middlewares/xframe.js:7:5)
    at async xssProtection (/Users/sherily/Desktop/Petcity/Repo/petcity-back/node_modules/egg-security/lib/middlewares/xssProtection.js:7:5)
    at async nosniff (/Users/sherily/Desktop/Petcity/Repo/petcity-back/node_modules/egg-security/lib/middlewares/nosniff.js:8:5)
    at async noopen (/Users/sherily/Desktop/Petcity/Repo/petcity-back/node_modules/egg-security/lib/middlewares/noopen.js:8:5)
    at async session (/Users/sherily/Desktop/Petcity/Repo/petcity-back/node_modules/koa-session/index.js:41:7)

pid: 36134
hostname: xiejialis-MacBook-Pro.local

2021-01-23 19:10:57,877 ERROR 36385 [-/192.168.31.88/-/14ms POST /api/v1/saveAvatar] nodejs.ReferenceError: pump is not defined
    at UserController.saveAvatar (/Users/sherily/Desktop/Petcity/Repo/petcity-back/app/controller/user.js:120:13)
    at processTicksAndRejections (node:internal/process/task_queues:93:5)
    at async /Users/sherily/Desktop/Petcity/Repo/petcity-back/node_modules/koa-static-cache/index.js:39:63
    at async robotMiddleware (/Users/sherily/Desktop/Petcity/Repo/petcity-back/app/middleware/robot.js:11:13)
    at async /Users/sherily/Desktop/Petcity/Repo/petcity-back/node_modules/egg-development/app/middleware/egg_loader_trace.js:9:50
    at async xframe (/Users/sherily/Desktop/Petcity/Repo/petcity-back/node_modules/egg-security/lib/middlewares/xframe.js:7:5)
    at async xssProtection (/Users/sherily/Desktop/Petcity/Repo/petcity-back/node_modules/egg-security/lib/middlewares/xssProtection.js:7:5)
    at async nosniff (/Users/sherily/Desktop/Petcity/Repo/petcity-back/node_modules/egg-security/lib/middlewares/nosniff.js:8:5)
    at async noopen (/Users/sherily/Desktop/Petcity/Repo/petcity-back/node_modules/egg-security/lib/middlewares/noopen.js:8:5)
    at async session (/Users/sherily/Desktop/Petcity/Repo/petcity-back/node_modules/koa-session/index.js:41:7)

pid: 36385
hostname: xiejialis-MacBook-Pro.local

2021-01-23 20:59:46,312 ERROR 36131 nodejs.ClusterClientNoResponseError: client no response in 109701ms exceeding maxIdleTime 60000ms, maybe the connection is close on other side.
    at Timeout._onTimeout (/Users/sherily/Desktop/Petcity/Repo/petcity-back/node_modules/cluster-client/lib/leader.js:77:23)
    at listOnTimeout (node:internal/timers:556:17)
    at processTimers (node:internal/timers:499:7)
name: "ClusterClientNoResponseError"
pid: 36131
hostname: xiejialis-MacBook-Pro.local

2021-01-23 21:28:01,467 ERROR 36131 nodejs.ClusterClientNoResponseError: client no response in 1654132ms exceeding maxIdleTime 60000ms, maybe the connection is close on other side.
    at Timeout._onTimeout (/Users/sherily/Desktop/Petcity/Repo/petcity-back/node_modules/cluster-client/lib/leader.js:77:23)
    at listOnTimeout (node:internal/timers:556:17)
    at processTimers (node:internal/timers:499:7)
name: "ClusterClientNoResponseError"
pid: 36131
hostname: xiejialis-MacBook-Pro.local

2021-01-23 22:01:54,446 ERROR 36131 nodejs.ClusterClientNoResponseError: client no response in 1992158ms exceeding maxIdleTime 60000ms, maybe the connection is close on other side.
    at Timeout._onTimeout (/Users/sherily/Desktop/Petcity/Repo/petcity-back/node_modules/cluster-client/lib/leader.js:77:23)
    at listOnTimeout (node:internal/timers:556:17)
    at processTimers (node:internal/timers:499:7)
name: "ClusterClientNoResponseError"
pid: 36131
hostname: xiejialis-MacBook-Pro.local

